Traceback (most recent call last):
  File "/home/runner/micromamba-root/envs/esm/lib/python3.11/site-packages/jupyter_cache/executors/utils.py", line 51, in single_nb_execution
    executenb(
  File "/home/runner/micromamba-root/envs/esm/lib/python3.11/site-packages/nbclient/client.py", line 1204, in execute
    return NotebookClient(nb=nb, resources=resources, km=km, **kwargs).execute()
           ^^^^^^^^^^^^^^^^^^^^^^^^^^^^^^^^^^^^^^^^^^^^^^^^^^^^^^^^^^^^^^^^^^^^^
  File "/home/runner/micromamba-root/envs/esm/lib/python3.11/site-packages/nbclient/util.py", line 84, in wrapped
    return just_run(coro(*args, **kwargs))
           ^^^^^^^^^^^^^^^^^^^^^^^^^^^^^^^
  File "/home/runner/micromamba-root/envs/esm/lib/python3.11/site-packages/nbclient/util.py", line 62, in just_run
    return loop.run_until_complete(coro)
           ^^^^^^^^^^^^^^^^^^^^^^^^^^^^^
  File "/home/runner/micromamba-root/envs/esm/lib/python3.11/asyncio/base_events.py", line 650, in run_until_complete
    return future.result()
           ^^^^^^^^^^^^^^^
  File "/home/runner/micromamba-root/envs/esm/lib/python3.11/contextlib.py", line 222, in __aexit__
    await self.gen.athrow(typ, value, traceback)
  File "/home/runner/micromamba-root/envs/esm/lib/python3.11/site-packages/nbclient/client.py", line 608, in async_setup_kernel
    yield
  File "/home/runner/micromamba-root/envs/esm/lib/python3.11/site-packages/nbclient/client.py", line 663, in async_execute
    await self.async_execute_cell(
  File "/home/runner/micromamba-root/envs/esm/lib/python3.11/site-packages/nbclient/client.py", line 965, in async_execute_cell
    await self._check_raise_for_error(cell, cell_index, exec_reply)
  File "/home/runner/micromamba-root/envs/esm/lib/python3.11/site-packages/nbclient/client.py", line 862, in _check_raise_for_error
    raise CellExecutionError.from_cell_and_msg(cell, exec_reply_content)
nbclient.exceptions.CellExecutionError: An error occurred while executing the following cell:
------------------
assert type(df.index) == pd.DatetimeIndex
------------------

[0;31m---------------------------------------------------------------------------[0m
[0;31mAssertionError[0m                            Traceback (most recent call last)
Cell [0;32mIn[85], line 1[0m
[0;32m----> 1[0m [38;5;28;01massert[39;00m [38;5;28mtype[39m(df[38;5;241m.[39mindex) [38;5;241m==[39m pd[38;5;241m.[39mDatetimeIndex

[0;31mAssertionError[0m: 
AssertionError: 

