Traceback (most recent call last):
  File "/home/runner/micromamba-root/envs/esm/lib/python3.9/site-packages/jupyter_cache/executors/utils.py", line 51, in single_nb_execution
    executenb(
  File "/home/runner/micromamba-root/envs/esm/lib/python3.9/site-packages/nbclient/client.py", line 1204, in execute
    return NotebookClient(nb=nb, resources=resources, km=km, **kwargs).execute()
  File "/home/runner/micromamba-root/envs/esm/lib/python3.9/site-packages/nbclient/util.py", line 84, in wrapped
    return just_run(coro(*args, **kwargs))
  File "/home/runner/micromamba-root/envs/esm/lib/python3.9/site-packages/nbclient/util.py", line 62, in just_run
    return loop.run_until_complete(coro)
  File "/home/runner/micromamba-root/envs/esm/lib/python3.9/asyncio/base_events.py", line 642, in run_until_complete
    return future.result()
  File "/home/runner/micromamba-root/envs/esm/lib/python3.9/site-packages/nbclient/client.py", line 663, in async_execute
    await self.async_execute_cell(
  File "/home/runner/micromamba-root/envs/esm/lib/python3.9/site-packages/nbclient/client.py", line 965, in async_execute_cell
    await self._check_raise_for_error(cell, cell_index, exec_reply)
  File "/home/runner/micromamba-root/envs/esm/lib/python3.9/site-packages/nbclient/client.py", line 862, in _check_raise_for_error
    raise CellExecutionError.from_cell_and_msg(cell, exec_reply_content)
nbclient.exceptions.CellExecutionError: An error occurred while executing the following cell:
------------------
clc = rasterio.open('../../materials/corine/U2018_CLC2018_V2020_20u1-PT.tif')
------------------

[0;31m---------------------------------------------------------------------------[0m
[0;31mCPLE_OpenFailedError[0m                      Traceback (most recent call last)
File [0;32mrasterio/_base.pyx:261[0m, in [0;36mrasterio._base.DatasetBase.__init__[0;34m()[0m

File [0;32mrasterio/_shim.pyx:78[0m, in [0;36mrasterio._shim.open_dataset[0;34m()[0m

File [0;32mrasterio/_err.pyx:215[0m, in [0;36mrasterio._err.exc_wrap_pointer[0;34m()[0m

[0;31mCPLE_OpenFailedError[0m: ../../materials/corine/U2018_CLC2018_V2020_20u1-PT.tif: No such file or directory

During handling of the above exception, another exception occurred:

[0;31mRasterioIOError[0m                           Traceback (most recent call last)
Cell [0;32mIn [9], line 1[0m
[0;32m----> 1[0m clc [38;5;241m=[39m [43mrasterio[49m[38;5;241;43m.[39;49m[43mopen[49m[43m([49m[38;5;124;43m'[39;49m[38;5;124;43m../../materials/corine/U2018_CLC2018_V2020_20u1-PT.tif[39;49m[38;5;124;43m'[39;49m[43m)[49m

File [0;32m~/micromamba-root/envs/esm/lib/python3.9/site-packages/rasterio/env.py:437[0m, in [0;36mensure_env_with_credentials.<locals>.wrapper[0;34m(*args, **kwds)[0m
[1;32m    434[0m     session [38;5;241m=[39m DummySession()
[1;32m    436[0m [38;5;28;01mwith[39;00m env_ctor(session[38;5;241m=[39msession):
[0;32m--> 437[0m     [38;5;28;01mreturn[39;00m [43mf[49m[43m([49m[38;5;241;43m*[39;49m[43margs[49m[43m,[49m[43m [49m[38;5;241;43m*[39;49m[38;5;241;43m*[39;49m[43mkwds[49m[43m)[49m

File [0;32m~/micromamba-root/envs/esm/lib/python3.9/site-packages/rasterio/__init__.py:220[0m, in [0;36mopen[0;34m(fp, mode, driver, width, height, count, crs, transform, dtype, nodata, sharing, **kwargs)[0m
[1;32m    216[0m [38;5;66;03m# Create dataset instances and pass the given env, which will[39;00m
[1;32m    217[0m [38;5;66;03m# be taken over by the dataset's context manager if it is not[39;00m
[1;32m    218[0m [38;5;66;03m# None.[39;00m
[1;32m    219[0m [38;5;28;01mif[39;00m mode [38;5;241m==[39m [38;5;124m'[39m[38;5;124mr[39m[38;5;124m'[39m:
[0;32m--> 220[0m     s [38;5;241m=[39m [43mDatasetReader[49m[43m([49m[43mpath[49m[43m,[49m[43m [49m[43mdriver[49m[38;5;241;43m=[39;49m[43mdriver[49m[43m,[49m[43m [49m[43msharing[49m[38;5;241;43m=[39;49m[43msharing[49m[43m,[49m[43m [49m[38;5;241;43m*[39;49m[38;5;241;43m*[39;49m[43mkwargs[49m[43m)[49m
[1;32m    221[0m [38;5;28;01melif[39;00m mode [38;5;241m==[39m [38;5;124m"[39m[38;5;124mr+[39m[38;5;124m"[39m:
[1;32m    222[0m     s [38;5;241m=[39m get_writer_for_path(path, driver[38;5;241m=[39mdriver)(
[1;32m    223[0m         path, mode, driver[38;5;241m=[39mdriver, sharing[38;5;241m=[39msharing, [38;5;241m*[39m[38;5;241m*[39mkwargs
[1;32m    224[0m     )

File [0;32mrasterio/_base.pyx:263[0m, in [0;36mrasterio._base.DatasetBase.__init__[0;34m()[0m

[0;31mRasterioIOError[0m: ../../materials/corine/U2018_CLC2018_V2020_20u1-PT.tif: No such file or directory
RasterioIOError: ../../materials/corine/U2018_CLC2018_V2020_20u1-PT.tif: No such file or directory

