Traceback (most recent call last):
  File "/home/runner/micromamba-root/envs/esm/lib/python3.9/site-packages/jupyter_cache/executors/utils.py", line 51, in single_nb_execution
    executenb(
  File "/home/runner/micromamba-root/envs/esm/lib/python3.9/site-packages/nbclient/client.py", line 1204, in execute
    return NotebookClient(nb=nb, resources=resources, km=km, **kwargs).execute()
  File "/home/runner/micromamba-root/envs/esm/lib/python3.9/site-packages/nbclient/util.py", line 84, in wrapped
    return just_run(coro(*args, **kwargs))
  File "/home/runner/micromamba-root/envs/esm/lib/python3.9/site-packages/nbclient/util.py", line 62, in just_run
    return loop.run_until_complete(coro)
  File "/home/runner/micromamba-root/envs/esm/lib/python3.9/asyncio/base_events.py", line 642, in run_until_complete
    return future.result()
  File "/home/runner/micromamba-root/envs/esm/lib/python3.9/site-packages/nbclient/client.py", line 663, in async_execute
    await self.async_execute_cell(
  File "/home/runner/micromamba-root/envs/esm/lib/python3.9/site-packages/nbclient/client.py", line 965, in async_execute_cell
    await self._check_raise_for_error(cell, cell_index, exec_reply)
  File "/home/runner/micromamba-root/envs/esm/lib/python3.9/site-packages/nbclient/client.py", line 862, in _check_raise_for_error
    raise CellExecutionError.from_cell_and_msg(cell, exec_reply_content)
nbclient.exceptions.CellExecutionError: An error occurred while executing the following cell:
------------------
G.remove_edge(2, 5)
------------------

[0;31m---------------------------------------------------------------------------[0m
[0;31mKeyError[0m                                  Traceback (most recent call last)
File [0;32m~/micromamba-root/envs/esm/lib/python3.9/site-packages/networkx/classes/graph.py:1053[0m, in [0;36mGraph.remove_edge[0;34m(self, u, v)[0m
[1;32m   1052[0m [38;5;28;01mtry[39;00m:
[0;32m-> 1053[0m     [38;5;28;01mdel[39;00m [38;5;28mself[39m[38;5;241m.[39m_adj[u][v]
[1;32m   1054[0m     [38;5;28;01mif[39;00m u [38;5;241m!=[39m v:  [38;5;66;03m# self-loop needs only one entry removed[39;00m

[0;31mKeyError[0m: 5

The above exception was the direct cause of the following exception:

[0;31mNetworkXError[0m                             Traceback (most recent call last)
Cell [0;32mIn [23], line 1[0m
[0;32m----> 1[0m [43mG[49m[38;5;241;43m.[39;49m[43mremove_edge[49m[43m([49m[38;5;241;43m2[39;49m[43m,[49m[43m [49m[38;5;241;43m5[39;49m[43m)[49m

File [0;32m~/micromamba-root/envs/esm/lib/python3.9/site-packages/networkx/classes/graph.py:1057[0m, in [0;36mGraph.remove_edge[0;34m(self, u, v)[0m
[1;32m   1055[0m         [38;5;28;01mdel[39;00m [38;5;28mself[39m[38;5;241m.[39m_adj[v][u]
[1;32m   1056[0m [38;5;28;01mexcept[39;00m [38;5;167;01mKeyError[39;00m [38;5;28;01mas[39;00m err:
[0;32m-> 1057[0m     [38;5;28;01mraise[39;00m NetworkXError([38;5;124mf[39m[38;5;124m"[39m[38;5;124mThe edge [39m[38;5;132;01m{[39;00mu[38;5;132;01m}[39;00m[38;5;124m-[39m[38;5;132;01m{[39;00mv[38;5;132;01m}[39;00m[38;5;124m is not in the graph[39m[38;5;124m"[39m) [38;5;28;01mfrom[39;00m [38;5;21;01merr[39;00m

[0;31mNetworkXError[0m: The edge 2-5 is not in the graph
NetworkXError: The edge 2-5 is not in the graph

