Traceback (most recent call last):
  File "/home/runner/micromamba-root/envs/esm/lib/python3.9/site-packages/jupyter_cache/executors/utils.py", line 51, in single_nb_execution
    executenb(
  File "/home/runner/micromamba-root/envs/esm/lib/python3.9/site-packages/nbclient/client.py", line 1204, in execute
    return NotebookClient(nb=nb, resources=resources, km=km, **kwargs).execute()
  File "/home/runner/micromamba-root/envs/esm/lib/python3.9/site-packages/nbclient/util.py", line 84, in wrapped
    return just_run(coro(*args, **kwargs))
  File "/home/runner/micromamba-root/envs/esm/lib/python3.9/site-packages/nbclient/util.py", line 62, in just_run
    return loop.run_until_complete(coro)
  File "/home/runner/micromamba-root/envs/esm/lib/python3.9/asyncio/base_events.py", line 642, in run_until_complete
    return future.result()
  File "/home/runner/micromamba-root/envs/esm/lib/python3.9/site-packages/nbclient/client.py", line 663, in async_execute
    await self.async_execute_cell(
  File "/home/runner/micromamba-root/envs/esm/lib/python3.9/site-packages/nbclient/client.py", line 965, in async_execute_cell
    await self._check_raise_for_error(cell, cell_index, exec_reply)
  File "/home/runner/micromamba-root/envs/esm/lib/python3.9/site-packages/nbclient/client.py", line 862, in _check_raise_for_error
    raise CellExecutionError.from_cell_and_msg(cell, exec_reply_content)
nbclient.exceptions.CellExecutionError: An error occurred while executing the following cell:
------------------
log = opt.solve(m, tee=True)
------------------

[0;31m---------------------------------------------------------------------------[0m
[0;31mApplicationError[0m                          Traceback (most recent call last)
Cell [0;32mIn [13], line 1[0m
[0;32m----> 1[0m log [38;5;241m=[39m [43mopt[49m[38;5;241;43m.[39;49m[43msolve[49m[43m([49m[43mm[49m[43m,[49m[43m [49m[43mtee[49m[38;5;241;43m=[39;49m[38;5;28;43;01mTrue[39;49;00m[43m)[49m

File [0;32m~/micromamba-root/envs/esm/lib/python3.9/site-packages/pyomo/opt/base/solvers.py:513[0m, in [0;36mOptSolver.solve[0;34m(self, *args, **kwds)[0m
[1;32m    510[0m [38;5;28;01mdef[39;00m [38;5;21msolve[39m([38;5;28mself[39m, [38;5;241m*[39margs, [38;5;241m*[39m[38;5;241m*[39mkwds):
[1;32m    511[0m     [38;5;124;03m""" Solve the problem """[39;00m
[0;32m--> 513[0m     [38;5;28;43mself[39;49m[38;5;241;43m.[39;49m[43mavailable[49m[43m([49m[43mexception_flag[49m[38;5;241;43m=[39;49m[38;5;28;43;01mTrue[39;49;00m[43m)[49m
[1;32m    514[0m     [38;5;66;03m#[39;00m
[1;32m    515[0m     [38;5;66;03m# If the inputs are models, then validate that they have been[39;00m
[1;32m    516[0m     [38;5;66;03m# constructed! Collect suffix names to try and import from solution.[39;00m
[1;32m    517[0m     [38;5;66;03m#[39;00m
[1;32m    518[0m     [38;5;28;01mfrom[39;00m [38;5;21;01mpyomo[39;00m[38;5;21;01m.[39;00m[38;5;21;01mcore[39;00m[38;5;21;01m.[39;00m[38;5;21;01mbase[39;00m[38;5;21;01m.[39;00m[38;5;21;01mblock[39;00m [38;5;28;01mimport[39;00m _BlockData

File [0;32m~/micromamba-root/envs/esm/lib/python3.9/site-packages/pyomo/opt/solver/shellcmd.py:129[0m, in [0;36mSystemCallSolver.available[0;34m(self, exception_flag)[0m
[1;32m    127[0m     [38;5;28;01mif[39;00m exception_flag:
[1;32m    128[0m         msg [38;5;241m=[39m [38;5;124m"[39m[38;5;124mNo executable found for solver [39m[38;5;124m'[39m[38;5;132;01m%s[39;00m[38;5;124m'[39m[38;5;124m"[39m
[0;32m--> 129[0m         [38;5;28;01mraise[39;00m ApplicationError(msg [38;5;241m%[39m [38;5;28mself[39m[38;5;241m.[39mname)
[1;32m    130[0m     [38;5;28;01mreturn[39;00m [38;5;28;01mFalse[39;00m
[1;32m    131[0m [38;5;28;01mreturn[39;00m [38;5;28;01mTrue[39;00m

[0;31mApplicationError[0m: No executable found for solver 'cbc'
ApplicationError: No executable found for solver 'cbc'

